---
title: 破事一堆
date : 2024-06-21 15:06:30 +0800
categories: [计算机, 笔记]
tags: [计算机, Linux]
---

## 用conda装pytorch装不上

TLNR：最后用pip装的。

用conda装pytorch

```sh
conda install pytorch torchvision torchaudio pytorch-cuda=12.1 -c pytorch -c nvidia
```

报错，估计是连不上pytorch和nvidia的网

```
Collecting package metadata (repodata.json): / Retrying (Retry(total=2, connect=None, read=None, redirect=None, status=None)) after connection broken by 'NewConnectionError('<urllib3.connection.HTTPSConnection object at 0x7f88049b5dd0>: Failed to establish a new connection: [Errno 101] Network is unreachable')': /nvidia/noarch/repodata.json.zst

Retrying (Retry(total=2, connect=None, read=None, redirect=None, status=None)) after connection broken by 'NewConnectionError('<urllib3.connection.HTTPSConnection object at 0x7f88049a2690>: Failed to establish a new connection: [Errno 101] Network is unreachable')': /pytorch/noarch/repodata.json.zst

Retrying (Retry(total=2, connect=None, read=None, redirect=None, status=None)) after connection broken by 'NewConnectionError('<urllib3.connection.HTTPSConnection object at 0x7f87ffe00910>: Failed to establish a new connection: [Errno 101] Network is unreachable')': /pytorch/linux-64/repodata.json.zst

Retrying (Retry(total=2, connect=None, read=None, redirect=None, status=None)) after connection broken by 'NewConnectionError('<urllib3.connection.HTTPSConnection object at 0x7f880806b0d0>: Failed to establish a new connection: [Errno 101] Network is unreachable')': /nvidia/linux-64/repodata.json.zst

| Retrying (Retry(total=1, connect=None, read=None, redirect=None, status=None)) after connection broken by 'NewConnectionError('<urllib3.connection.HTTPSConnection object at 0x7f88048f3ed0>: Failed to establish a new connection: [Errno 101] Network is unreachable')': /pytorch/linux-64/repodata.json.zst

Retrying (Retry(total=1, connect=None, read=None, redirect=None, status=None)) after connection broken by 'NewConnectionError('<urllib3.connection.HTTPSConnection object at 0x7f8808002e50>: Failed to establish a new connection: [Errno 101] Network is unreachable')': /pytorch/noarch/repodata.json.zst

Retrying (Retry(total=1, connect=None, read=None, redirect=None, status=None)) after connection broken by 'NewConnectionError('<urllib3.connection.HTTPSConnection object at 0x7f88080037d0>: Failed to establish a new connection: [Errno 101] Network is unreachable')': /nvidia/noarch/repodata.json.zst

Retrying (Retry(total=1, connect=None, read=None, redirect=None, status=None)) after connection broken by 'NewConnectionError('<urllib3.connection.HTTPSConnection object at 0x7f87ffd23ad0>: Failed to establish a new connection: [Errno 101] Network is unreachable')': /nvidia/linux-64/repodata.json.zst

\ Retrying (Retry(total=0, connect=None, read=None, redirect=None, status=None)) after connection broken by 'NewConnectionError('<urllib3.connection.HTTPSConnection object at 0x7f88049a1890>: Failed to establish a new connection: [Errno 101] Network is unreachable')': /pytorch/linux-64/repodata.json.zst

Retrying (Retry(total=0, connect=None, read=None, redirect=None, status=None)) after connection broken by 'NewConnectionError('<urllib3.connection.HTTPSConnection object at 0x7f88049a14d0>: Failed to establish a new connection: [Errno 101] Network is unreachable')': /pytorch/noarch/repodata.json.zst

Retrying (Retry(total=0, connect=None, read=None, redirect=None, status=None)) after connection broken by 'NewConnectionError('<urllib3.connection.HTTPSConnection object at 0x7f88049a3950>: Failed to establish a new connection: [Errno 101] Network is unreachable')': /nvidia/linux-64/repodata.json.zst

Retrying (Retry(total=0, connect=None, read=None, redirect=None, status=None)) after connection broken by 'NewConnectionError('<urllib3.connection.HTTPSConnection object at 0x7f88049a2ad0>: Failed to establish a new connection: [Errno 101] Network is unreachable')': /nvidia/noarch/repodata.json.zst

failed

CondaHTTPError: HTTP 000 CONNECTION FAILED for url <https://conda.anaconda.org/pytorch/linux-64/repodata.json>
Elapsed: -

An HTTP error occurred when trying to retrieve this URL.
HTTP errors are often intermittent, and a simple retry will get you on your way.
'https//conda.anaconda.org/pytorch/linux-64'
```

默认的源

```sh
conda install pytorch torchvision torchaudio pytorch-cuda=12.1
```

找不到pytorch-cuda和torchaudio

```
Channels:
 - defaults
 - https://mirrors.tuna.tsinghua.edu.cn/anaconda/cloud/conda-forge
Platform: linux-64
Collecting package metadata (repodata.json): done
Solving environment: failed

PackagesNotFoundError: The following packages are not available from current channels:

  - pytorch-cuda=12.1*
  - torchaudio

Current channels:

  - defaults
  - https://mirrors.tuna.tsinghua.edu.cn/anaconda/cloud/conda-forge/linux-64
  - https://mirrors.tuna.tsinghua.edu.cn/anaconda/cloud/conda-forge/noarch

To search for alternate channels that may provide the conda package you're
looking for, navigate to

    https://anaconda.org

and use the search bar at the top of the page.
```

到[清华镜像站](https://mirrors.tuna.tsinghua.edu.cn/anaconda/cloud/pytorch/win-64/)本地下载对应版本，然后本地安装：

```sh
conda install pytorch-2.3.1-py3.12_cuda12.1_cudnn8_0.tar.bz2
```

`conda list`显示装上了，试试是否可用。

```py
import torch
torch.cuda
```

至少没装完整

```
Traceback (most recent call last):
  File "<stdin>", line 1, in <module>
AttributeError: module 'torch' has no attribute 'cuda'
```

卸了，加了更多镜像，但还是不行，libcublas安装不上。

```sh
conda config --add channels https://mirrors.tuna.tsinghua.edu.cn/anaconda/pkgs/free/
conda config --add channels https://mirrors.tuna.tsinghua.edu.cn/anaconda/pkgs/main/
conda config --add channels https://mirrors.tuna.tsinghua.edu.cn/anaconda/cloud/msys2/
conda config --add channels https://mirrors.tuna.tsinghua.edu.cn/anaconda/cloud/bioconda/
conda config --add channels https://mirrors.tuna.tsinghua.edu.cn/anaconda/cloud/menpo/
conda config --add channels https://mirrors.tuna.tsinghua.edu.cn/anaconda/cloud/pytorch/
conda config --set show_channel_urls yes
```

```
Channels:
 - https://mirrors.tuna.tsinghua.edu.cn/anaconda/cloud/pytorch
 - https://mirrors.tuna.tsinghua.edu.cn/anaconda/cloud/menpo
 - https://mirrors.tuna.tsinghua.edu.cn/anaconda/cloud/bioconda
 - https://mirrors.tuna.tsinghua.edu.cn/anaconda/cloud/msys2
 - https://mirrors.tuna.tsinghua.edu.cn/anaconda/cloud/conda-forge
 - https://mirrors.tuna.tsinghua.edu.cn/anaconda/pkgs/main
 - https://mirrors.tuna.tsinghua.edu.cn/anaconda/pkgs/free
 - https://mirrors.tuna.tsinghua.edu.cn/anaconda/pkgs/msys2
 - https://mirrors.tuna.tsinghua.edu.cn/anaconda/pkgs/r
 - defaults
Platform: linux-64
Collecting package metadata (repodata.json): done
Solving environment: failed

LibMambaUnsatisfiableError: Encountered problems while solving:
  - nothing provides libcublas >=12.1.0.26,<12.1.3.1 needed by pytorch-cuda-12.1-ha16c6d3_5

Could not solve for environment specs
The following package could not be installed
└─ pytorch-cuda 12.1**  is not installable because it requires
   └─ libcublas >=12.1.0.26,<12.1.3.1 , which does not exist (perhaps a missing channel).
```

应该是恰好没这个版本的libcublas，其他源也下不到，直接去nvidia[那里](https://anaconda.org/nvidia/libcublas/files)下了一个，本地安装

```
Could not solve for environment specs
The following package could not be installed
└─ pytorch-cuda 12.1**  is not installable because it requires
   └─ libcufft >=11.0.2.4,<11.0.2.54 , which does not exist (perhaps a missing channel).
```

好家伙，这一个个的不会都让我本地安装吧。

装了几个之后，发现了安装冲突：

```
Could not solve for environment specs
The following package could not be installed
└─ pytorch-cuda 12.1**  is not installable because it requires
   ├─ cuda-libraries >=12.1,<12.2 , which requires
   │  └─ libcublas 12.1.3.1.* , which can be installed;
   └─ libcublas >=12.1.0.26,<12.1.3.1 , which conflicts with any installable versions previously reported.
```

最后拿pip装了

```sh
pip3 install torch torchvision torchaudio --index-url https://download.pytorch.org/whl/cu121
```

```
>>> import torch
tor>>> torch.cuda
<module 'torch.cuda' from '/home/ubuntu/anaconda3/envs/llm/lib/python3.12/site-packages/torch/cuda/__init__.py'>
>>> torch.cuda.is_avaliable
Traceback (most recent call last):
  File "<stdin>", line 1, in <module>
AttributeError: module 'torch.cuda' has no attribute 'is_avaliable'. Did you mean: 'is_available'?
>>> torch.cuda.is_available()
True
```

## 在远程端没python环境

在远程端安装python插件等。

似乎是网的问题，有点装不上，本地安装，下载vsix文件，比如[python](https://marketplace.visualstudio.com/items?itemName=ms-python.python)，点击`Download Extension`，下载好后放到远程端，插件页面右上角三个点，从vsix安装。

```
Unable to install extension 'ms-python.python' as it is not compatible with VS Code '1.83.0'.
```

应该是我vscode版本需要更新了，更新了一下vscode，便携版只要保留`data`文件夹就好了。

结果网好像又好了，能直接在插件商店安装了，所以说不定之前不能安装是因为我vscode版本太旧了。

jupyter跑不了，需要ipykernal，结果又安装不上去了，但是这次报错给了信息

```
运行具有“llm (Python 3.12.4)”的单元格需要ipykernel包。
运行以下命令，将 "ipykernel" 安装到 Python 环境中。
命令: "conda install -n llm ipykernel --update-deps --force-reinstall"
```

llm是我环境的名字。

## 安装gym时找不到rendering文件

从[这里](https://github.com/openai/gym/blob/0cd9266d986d470ed9c0dd87a41cd680b65cfe1c/gym/envs/classic_control/rendering.py#L18)下载后安装到`gym/envs/classic_control`。

话说为什么会少个文件啊。

## 安装gym[box2d]失败

报错

```
Looking in indexes: https://pypi.tuna.tsinghua.edu.cn/simple
Requirement already satisfied: gym[box2d] in g:\software\anaconda3\envs\torch\lib\site-packages (0.26.2)
Requirement already satisfied: numpy>=1.18.0 in g:\software\anaconda3\envs\torch\lib\site-packages (from gym[box2d]) (1.26.4)
Requirement already satisfied: cloudpickle>=1.2.0 in g:\software\anaconda3\envs\torch\lib\site-packages (from gym[box2d]) (3.0.0)
Requirement already satisfied: gym-notices>=0.0.4 in g:\software\anaconda3\envs\torch\lib\site-packages (from gym[box2d]) (0.0.8)
Collecting box2d-py==2.3.5 (from gym[box2d])
  Using cached https://pypi.tuna.tsinghua.edu.cn/packages/dd/5a/ad8d3ef9c13d5afcc1e44a77f11792ee717f6727b3320bddbc607e935e2a/box2d-py-2.3.5.tar.gz (374 kB)
  Preparing metadata (setup.py) ... done
Collecting pygame==2.1.0 (from gym[box2d])
  Using cached https://pypi.tuna.tsinghua.edu.cn/packages/e0/ce/1215d864989d25cb7b234759ce6a760813dffe2e707df7f8e3e748538ba0/pygame-2.1.0-cp310-cp310-win_amd64.whl (4.8 MB)
Collecting swig==4.* (from gym[box2d])
  Using cached https://pypi.tuna.tsinghua.edu.cn/packages/d0/ef/44fb7b4216530551460666286ec04424d34f4a25e8fba1cebe742a24e012/swig-4.2.1-py2.py3-none-win_amd64.whl (2.6 MB)
Building wheels for collected packages: box2d-py
  Building wheel for box2d-py (setup.py) ... error
  error: subprocess-exited-with-error

  × python setup.py bdist_wheel did not run successfully.
  │ exit code: 1
  ╰─> [16 lines of output]
      Using setuptools (version 67.8.0).
      running bdist_wheel
      running build
      running build_py
      creating build
      creating build\lib.win-amd64-cpython-310
      creating build\lib.win-amd64-cpython-310\Box2D
      copying library\Box2D\Box2D.py -> build\lib.win-amd64-cpython-310\Box2D
      copying library\Box2D\__init__.py -> build\lib.win-amd64-cpython-310\Box2D
      creating build\lib.win-amd64-cpython-310\Box2D\b2
      copying library\Box2D\b2\__init__.py -> build\lib.win-amd64-cpython-310\Box2D\b2
      running build_ext
      building 'Box2D._Box2D' extension
      swigging Box2D\Box2D.i to Box2D\Box2D_wrap.cpp
      swig.exe -python -c++ -IBox2D -small -O -includeall -ignoremissing -w201 -globals b2Globals -outdir library\Box2D -keyword -w511 -D_SWIG_KWARGS -o Box2D\Box2D_wrap.cpp Box2D\Box2D.i
      error: command 'swig.exe' failed: None
      [end of output]

  note: This error originates from a subprocess, and is likely not a problem with pip.
  ERROR: Failed building wheel for box2d-py
  Running setup.py clean for box2d-py
Failed to build box2d-py
ERROR: Could not build wheels for box2d-py, which is required to install pyproject.toml-based projects
```

用conda装据说可以，但是我装不上

```bash
pip install ufal.pybox2d
```
这个可以

## 将python程序变成exe

pip安装pyinstaller

```bash
pyinstaller -y -F -w -n demodemo.py
```
-F是单文件、-w是无控制台（如果要用到`input()`等函数要去掉）
